data/output/REX.txt
PASSIVE SELL 1500.00 @ 14.03
PASSIVE BUY 2140.00 @ 13.84
PASSIVE BUY 2420.00 @ 13.92
AGGRESSIVE BUY 780.00 @ 14.03
AGGRESSIVE BUY 2060.00 @ 14.03
PASSIVE SELL 940.00 @ 14.09
AGGRESSIVE BUY 1500.00 @ 14.15
AGGRESSIVE SELL 860.00 @ 14.13
PASSIVE BUY 1220.00 @ 13.91
PASSIVE SELL 660.00 @ 14.15
PASSIVE BUY 2180.00 @ 14.09
AGGRESSIVE SELL 380.00 @ 14.09
PASSIVE SELL 1300.00 @ 14.13
AGGRESSIVE SELL 1740.00 @ 14.09
PASSIVE SELL 580.00 @ 14.13
PASSIVE BUY 2500.00 @ 14.12
PASSIVE SELL 1220.00 @ 14.22
AGGRESSIVE BUY 1900.00 @ 14.13
AGGRESSIVE BUY 1580.00 @ 14.15
CANCEL BUY 2140.00 @ 13.84
CANCEL BUY 2420.00 @ 13.92
CANCEL BUY 1340.00 @ 14.03
CANCEL BUY 1220.00 @ 13.91
CANCEL BUY 60.00 @ 14.09
CANCEL BUY 2500.00 @ 14.12
CANCEL BUY 640.00 @ 14.15
AGGRESSIVE BUY 2660.00 @ 14.30
PASSIVE BUY 1380.00 @ 14.21
PASSIVE BUY 2060.00 @ 14.45
AGGRESSIVE SELL 1020.00 @ 14.45
PASSIVE BUY 2260.00 @ 14.38
AGGRESSIVE SELL 2220.00 @ 14.38
AGGRESSIVE SELL 2300.00 @ 14.30
PASSIVE SELL 2100.00 @ 14.32
AGGRESSIVE BUY 1260.00 @ 14.32
PASSIVE SELL 1780.00 @ 14.32
PASSIVE SELL 2300.00 @ 14.39
PASSIVE BUY 2700.00 @ 14.25
AGGRESSIVE SELL 2100.00 @ 14.28
AGGRESSIVE BUY 1300.00 @ 14.28
AGGRESSIVE BUY 780.00 @ 14.32
PASSIVE SELL 1860.00 @ 14.40
AGGRESSIVE BUY 2140.00 @ 14.32
PASSIVE BUY 1020.00 @ 14.23
PASSIVE BUY 2300.00 @ 14.15
PASSIVE SELL 1100.00 @ 14.38
AGGRESSIVE BUY 2700.00 @ 14.39
PASSIVE SELL 1700.00 @ 14.41
AGGRESSIVE BUY 2300.00 @ 14.40
PASSIVE SELL 420.00 @ 14.33
PASSIVE BUY 740.00 @ 14.22
AGGRESSIVE BUY 2180.00 @ 14.36
AGGRESSIVE SELL 500.00 @ 14.36
PASSIVE BUY 1620.00 @ 14.23
AGGRESSIVE BUY 2660.00 @ 14.49
CANCEL BUY 1380.00 @ 14.21
CANCEL BUY 2700.00 @ 14.25
CANCEL BUY -1020.00 @ 14.23
CANCEL BUY 2300.00 @ 14.15
CANCEL BUY 740.00 @ 14.22
CANCEL BUY 1260.00 @ 14.36
CANCEL BUY 1620.00 @ 14.23
CANCEL BUY 420.00 @ 14.49
PASSIVE BUY 1900.00 @ 13.91
PASSIVE SELL 860.00 @ 14.54
PASSIVE BUY 980.00 @ 14.09
PASSIVE BUY 2420.00 @ 14.08
PASSIVE BUY 1660.00 @ 14.16
PASSIVE SELL 620.00 @ 14.55
PASSIVE SELL 1100.00 @ 14.41
PASSIVE BUY 1340.00 @ 14.21
PASSIVE BUY 1060.00 @ 14.25
PASSIVE BUY 1820.00 @ 14.20
CANCEL BUY 1900.00 @ 13.91
CANCEL BUY 980.00 @ 14.09
CANCEL BUY 2420.00 @ 14.08
CANCEL BUY 1660.00 @ 14.16
CANCEL BUY 1340.00 @ 14.21
CANCEL BUY 1060.00 @ 14.25
CANCEL BUY 1820.00 @ 14.20
PASSIVE BUY 1140.00 @ 14.22
PASSIVE BUY 2340.00 @ 14.19
PASSIVE SELL 820.00 @ 14.45
PASSIVE SELL 2260.00 @ 14.42
PASSIVE BUY 2700.00 @ 14.33
AGGRESSIVE SELL 1500.00 @ 14.33
AGGRESSIVE SELL 1580.00 @ 14.30
PASSIVE SELL 2100.00 @ 14.24
CANCEL SELL 620.00 @ 14.55
AGGRESSIVE SELL 1180.00 @ 14.19
AGGRESSIVE BUY 1500.00 @ 14.24
PASSIVE SELL 900.00 @ 14.37
CANCEL SELL 860.00 @ 14.54
PASSIVE SELL 380.00 @ 14.37
AGGRESSIVE SELL 2060.00 @ 14.19
AGGRESSIVE BUY 820.00 @ 14.30
PASSIVE BUY 1100.00 @ 14.08
PASSIVE SELL 2300.00 @ 14.38
PASSIVE SELL 2180.00 @ 14.32
CANCEL SELL 820.00 @ 14.45
PASSIVE BUY 2420.00 @ 14.20
PASSIVE SELL 420.00 @ 14.36
CANCEL SELL 2260.00 @ 14.42
PASSIVE BUY 2460.00 @ 14.15
PASSIVE BUY 1460.00 @ 14.21
PASSIVE SELL 2140.00 @ 14.31
CANCEL SELL 1100.00 @ 14.41
PASSIVE SELL 380.00 @ 14.42
CANCEL SELL 380.00 @ 14.42
AGGRESSIVE SELL 460.00 @ 14.21
PASSIVE SELL 500.00 @ 14.36
PASSIVE SELL 1340.00 @ 14.35
CANCEL SELL 2300.00 @ 14.38
PASSIVE SELL 1500.00 @ 14.40
CANCEL SELL 1500.00 @ 14.40
PASSIVE SELL 1140.00 @ 14.37
AGGRESSIVE BUY 1300.00 @ 14.31
PASSIVE SELL 980.00 @ 14.43
PASSIVE BUY 2700.00 @ 14.21
PASSIVE SELL 1220.00 @ 14.22
CANCEL SELL 980.00 @ 14.43
AGGRESSIVE SELL 620.00 @ 14.21
AGGRESSIVE SELL 860.00 @ 14.21
PASSIVE SELL 2060.00 @ 14.29
CANCEL SELL -900.00 @ 14.37
CANCEL SELL -380.00 @ 14.37
CANCEL SELL 1140.00 @ 14.37
AGGRESSIVE BUY 2260.00 @ 14.22
AGGRESSIVE SELL 1060.00 @ 14.21
PASSIVE SELL 1620.00 @ 14.23
AGGRESSIVE SELL 1500.00 @ 14.21
PASSIVE BUY 1700.00 @ 14.10
PASSIVE SELL 1060.00 @ 14.36
PASSIVE BUY 1420.00 @ 14.12
CANCEL BUY 240.00 @ 14.19
CANCEL BUY 1100.00 @ 14.08
CANCEL BUY 2420.00 @ 14.20
CANCEL BUY 2460.00 @ 14.15
CANCEL BUY 700.00 @ 14.21
CANCEL BUY 1700.00 @ 14.10
CANCEL BUY 1420.00 @ 14.12
PASSIVE BUY 1860.00 @ 14.17
AGGRESSIVE BUY 2140.00 @ 14.29
PASSIVE BUY 820.00 @ 14.21
PASSIVE SELL 1060.00 @ 14.40
AGGRESSIVE BUY 2420.00 @ 14.31
PASSIVE BUY 1580.00 @ 14.20
AGGRESSIVE BUY 2260.00 @ 14.32
AGGRESSIVE SELL 1220.00 @ 14.20
AGGRESSIVE SELL 1380.00 @ 14.17
PASSIVE SELL 1220.00 @ 14.38
PASSIVE SELL 2300.00 @ 14.27
AGGRESSIVE BUY 2740.00 @ 14.27
PASSIVE SELL 1380.00 @ 14.34
PASSIVE SELL 700.00 @ 14.40
AGGRESSIVE SELL 420.00 @ 14.27
PASSIVE SELL 1100.00 @ 14.37
CANCEL SELL -1060.00 @ 14.40
CANCEL SELL 700.00 @ 14.40
PASSIVE SELL 1700.00 @ 14.29
CANCEL SELL 1220.00 @ 14.38
PASSIVE BUY 1180.00 @ 14.23
AGGRESSIVE SELL 1300.00 @ 14.26
CANCEL SELL 1100.00 @ 14.37
PASSIVE SELL 1700.00 @ 14.28
CANCEL SELL -420.00 @ 14.36
CANCEL SELL -500.00 @ 14.36
CANCEL SELL 1060.00 @ 14.36
AGGRESSIVE SELL 580.00 @ 14.23
PASSIVE BUY 1780.00 @ 14.19
PASSIVE BUY 1100.00 @ 14.24
PASSIVE SELL 1340.00 @ 14.37
CANCEL SELL 1340.00 @ 14.37
AGGRESSIVE SELL 1620.00 @ 14.23
AGGRESSIVE SELL 1740.00 @ 14.19
PASSIVE BUY 1300.00 @ 14.19
PASSIVE BUY 2220.00 @ 14.09
PASSIVE SELL 1780.00 @ 14.21
CANCEL SELL 1340.00 @ 14.35
PASSIVE BUY 2060.00 @ 14.15
AGGRESSIVE BUY 2300.00 @ 14.23
AGGRESSIVE BUY 1940.00 @ 14.27
AGGRESSIVE SELL 1100.00 @ 14.23
PASSIVE BUY 1180.00 @ 14.11
PASSIVE SELL 1740.00 @ 14.32
AGGRESSIVE SELL 1020.00 @ 14.19
PASSIVE SELL 900.00 @ 14.42
AGGRESSIVE BUY 2900.00 @ 14.29
PASSIVE BUY 2660.00 @ 14.15
AGGRESSIVE SELL 860.00 @ 14.18
PASSIVE BUY 1460.00 @ 14.08
PASSIVE BUY 1740.00 @ 14.14
PASSIVE SELL 1660.00 @ 14.21
AGGRESSIVE SELL 1340.00 @ 14.17
PASSIVE SELL 2140.00 @ 14.32
PASSIVE BUY 1060.00 @ 14.12
CANCEL BUY 320.00 @ 14.17
CANCEL BUY 2220.00 @ 14.09
CANCEL BUY -2060.00 @ 14.15
CANCEL BUY 1180.00 @ 14.11
CANCEL BUY 2660.00 @ 14.15
CANCEL BUY 1460.00 @ 14.08
CANCEL BUY 1740.00 @ 14.14
CANCEL BUY 1060.00 @ 14.12
PASSIVE SELL 1860.00 @ 14.18
PASSIVE BUY 2380.00 @ 14.17
PASSIVE BUY 1180.00 @ 14.15
PASSIVE BUY 2460.00 @ 14.17
AGGRESSIVE SELL 1620.00 @ 14.17
AGGRESSIVE SELL 1180.00 @ 14.17
PASSIVE SELL 460.00 @ 14.19
CANCEL SELL 900.00 @ 14.42
AGGRESSIVE SELL 620.00 @ 14.17
AGGRESSIVE SELL 1500.00 @ 14.15
PASSIVE SELL 1220.00 @ 14.32
PASSIVE BUY 2700.00 @ 14.07
PASSIVE BUY 2340.00 @ 14.06
AGGRESSIVE BUY 900.00 @ 14.18
PASSIVE BUY 1860.00 @ 14.08
PASSIVE BUY 2860.00 @ 14.05
PASSIVE SELL 540.00 @ 14.19
AGGRESSIVE BUY 1340.00 @ 14.18
AGGRESSIVE SELL 1860.00 @ 14.08
AGGRESSIVE BUY 1260.00 @ 14.21
PASSIVE BUY 2100.00 @ 14.01
PASSIVE BUY 900.00 @ 14.12
AGGRESSIVE SELL 1860.00 @ 14.08
AGGRESSIVE SELL 1620.00 @ 14.07
PASSIVE SELL 1220.00 @ 14.26
PASSIVE SELL 2180.00 @ 14.09
AGGRESSIVE SELL 1260.00 @ 14.06
PASSIVE BUY 1620.00 @ 13.99
PASSIVE SELL 740.00 @ 14.21
PASSIVE BUY 2660.00 @ 14.08
PASSIVE BUY 2740.00 @ 13.99
PASSIVE BUY 2580.00 @ 13.93
AGGRESSIVE BUY 1540.00 @ 14.09
AGGRESSIVE SELL 820.00 @ 14.08
PASSIVE SELL 860.00 @ 14.23
CANCEL SELL 1380.00 @ 14.34
PASSIVE BUY 2700.00 @ 13.93
PASSIVE BUY 1140.00 @ 13.97
CANCEL BUY 2300.00 @ 14.06
CANCEL BUY 2860.00 @ 14.05
CANCEL BUY 2100.00 @ 14.01
CANCEL BUY -1620.00 @ 13.99
CANCEL BUY 1840.00 @ 14.08
CANCEL BUY 2740.00 @ 13.99
CANCEL BUY -2580.00 @ 13.93
CANCEL BUY 2700.00 @ 13.93
CANCEL BUY 1140.00 @ 13.97
PASSIVE BUY 2660.00 @ 14.08
AGGRESSIVE BUY 1220.00 @ 14.09
AGGRESSIVE SELL 1340.00 @ 14.08
PASSIVE SELL 1420.00 @ 14.15
PASSIVE SELL 2180.00 @ 14.23
PASSIVE SELL 940.00 @ 14.11
CANCEL SELL -40.00 @ 14.32
CANCEL SELL -1740.00 @ 14.32
CANCEL SELL -2140.00 @ 14.32
CANCEL SELL 1220.00 @ 14.32
PASSIVE SELL 2100.00 @ 14.16
CANCEL SELL 500.00 @ 14.29
PASSIVE SELL 1300.00 @ 14.16
AGGRESSIVE SELL 940.00 @ 14.08
PASSIVE SELL 1060.00 @ 14.20
CANCEL SELL 1220.00 @ 14.26
PASSIVE BUY 2940.00 @ 13.98
AGGRESSIVE BUY 980.00 @ 14.15
AGGRESSIVE SELL 1540.00 @ 14.07
AGGRESSIVE BUY 820.00 @ 14.11
AGGRESSIVE SELL 860.00 @ 14.07
PASSIVE SELL 1180.00 @ 14.07
AGGRESSIVE SELL 1860.00 @ 13.98
PASSIVE BUY 2860.00 @ 13.86
AGGRESSIVE BUY 2700.00 @ 14.10
AGGRESSIVE BUY 1620.00 @ 14.16
PASSIVE BUY 2180.00 @ 14.12
