data/output/SMGR.txt
PASSIVE BUY 780.00 @ 243.90
PASSIVE SELL 980.00 @ 244.17
PASSIVE SELL 2260.00 @ 244.02
PASSIVE SELL 540.00 @ 243.94
PASSIVE BUY 780.00 @ 243.87
PASSIVE BUY 1380.00 @ 243.93
PASSIVE SELL 1340.00 @ 244.03
AGGRESSIVE BUY 2620.00 @ 243.99
AGGRESSIVE BUY 900.00 @ 244.02
AGGRESSIVE BUY 2460.00 @ 244.03
AGGRESSIVE SELL 1100.00 @ 243.99
AGGRESSIVE BUY 2900.00 @ 244.10
PASSIVE BUY 1180.00 @ 244.16
AGGRESSIVE BUY 2460.00 @ 244.29
CANCEL BUY 780.00 @ 243.90
CANCEL BUY 780.00 @ 243.87
CANCEL BUY 1380.00 @ 243.93
CANCEL BUY 980.00 @ 243.99
CANCEL BUY 2660.00 @ 244.10
CANCEL BUY 1180.00 @ 244.16
CANCEL BUY 1480.00 @ 244.29
PASSIVE BUY 2220.00 @ 243.83
PASSIVE BUY 1620.00 @ 243.80
PASSIVE BUY 1780.00 @ 243.81
PASSIVE BUY 2300.00 @ 243.82
PASSIVE SELL 820.00 @ 244.48
PASSIVE BUY 1420.00 @ 243.74
PASSIVE SELL 1300.00 @ 244.40
PASSIVE SELL 420.00 @ 244.38
PASSIVE SELL 420.00 @ 244.45
PASSIVE SELL 420.00 @ 244.26
PASSIVE SELL 700.00 @ 244.31
PASSIVE BUY 1460.00 @ 243.71
PASSIVE SELL 1780.00 @ 244.26
PASSIVE SELL 2020.00 @ 244.14
CANCEL SELL 820.00 @ 244.48
PASSIVE BUY 2060.00 @ 243.97
CANCEL BUY 2220.00 @ 243.83
CANCEL BUY 1620.00 @ 243.80
CANCEL BUY 1780.00 @ 243.81
CANCEL BUY 2300.00 @ 243.82
CANCEL BUY 1420.00 @ 243.74
CANCEL BUY 1460.00 @ 243.71
CANCEL BUY 2060.00 @ 243.97
PASSIVE BUY 780.00 @ 244.11
AGGRESSIVE SELL 1780.00 @ 243.98
CANCEL SELL 420.00 @ 244.45
AGGRESSIVE BUY 1220.00 @ 244.03
AGGRESSIVE SELL 1980.00 @ 244.00
AGGRESSIVE BUY 1140.00 @ 244.00
AGGRESSIVE BUY 2860.00 @ 244.10
PASSIVE BUY 1380.00 @ 244.02
AGGRESSIVE BUY 860.00 @ 244.14
AGGRESSIVE BUY 2540.00 @ 244.14
PASSIVE SELL 1900.00 @ 244.20
PASSIVE SELL 1340.00 @ 244.15
PASSIVE SELL 1980.00 @ 244.20
PASSIVE BUY 2940.00 @ 244.06
PASSIVE BUY 1540.00 @ 244.14
PASSIVE BUY 1980.00 @ 244.07
PASSIVE BUY 980.00 @ 244.05
AGGRESSIVE SELL 1100.00 @ 244.14
AGGRESSIVE BUY 2900.00 @ 244.15
CANCEL BUY 2240.00 @ 244.10
CANCEL BUY 1380.00 @ 244.02
CANCEL BUY -280.00 @ 244.14
CANCEL BUY 2940.00 @ 244.06
CANCEL BUY 1540.00 @ 244.14
CANCEL BUY 1980.00 @ 244.07
CANCEL BUY 980.00 @ 244.05
CANCEL BUY 1560.00 @ 244.15
PASSIVE SELL 1940.00 @ 244.21
PASSIVE BUY 1740.00 @ 244.13
PASSIVE SELL 1460.00 @ 244.31
PASSIVE SELL 780.00 @ 244.15
CANCEL SELL 1300.00 @ 244.40
AGGRESSIVE SELL 1340.00 @ 244.13
AGGRESSIVE SELL 1020.00 @ 244.06
CANCEL SELL 420.00 @ 244.38
PASSIVE BUY 1500.00 @ 243.98
PASSIVE SELL 660.00 @ 244.03
CANCEL SELL -700.00 @ 244.31
CANCEL SELL 1460.00 @ 244.31
PASSIVE SELL 820.00 @ 244.00
CANCEL SELL -420.00 @ 244.26
CANCEL SELL 1780.00 @ 244.26
AGGRESSIVE BUY 1300.00 @ 244.03
AGGRESSIVE SELL 500.00 @ 243.98
AGGRESSIVE SELL 1620.00 @ 243.92
AGGRESSIVE BUY 2180.00 @ 244.02
PASSIVE BUY 1580.00 @ 243.93
PASSIVE BUY 1860.00 @ 244.02
PASSIVE SELL 1420.00 @ 244.15
AGGRESSIVE BUY 980.00 @ 244.10
AGGRESSIVE BUY 1340.00 @ 244.15
PASSIVE BUY 1980.00 @ 244.10
PASSIVE SELL 900.00 @ 244.24
PASSIVE BUY 1900.00 @ 244.13
PASSIVE SELL 1220.00 @ 244.25
PASSIVE BUY 1940.00 @ 244.05
AGGRESSIVE BUY 2740.00 @ 244.20
PASSIVE SELL 900.00 @ 244.18
PASSIVE BUY 2020.00 @ 244.02
AGGRESSIVE BUY 2540.00 @ 244.18
AGGRESSIVE SELL 1940.00 @ 244.13
AGGRESSIVE SELL 460.00 @ 244.13
AGGRESSIVE BUY 980.00 @ 244.20
PASSIVE BUY 2020.00 @ 244.05
PASSIVE BUY 2860.00 @ 244.17
PASSIVE SELL 820.00 @ 244.21
AGGRESSIVE SELL 580.00 @ 244.17
PASSIVE SELL 420.00 @ 244.27
PASSIVE SELL 1740.00 @ 244.20
AGGRESSIVE SELL 820.00 @ 244.17
PASSIVE BUY 1140.00 @ 244.07
CANCEL BUY -1560.00 @ 244.02
CANCEL BUY 1580.00 @ 243.93
CANCEL BUY -1860.00 @ 244.02
CANCEL BUY -180.00 @ 244.10
CANCEL BUY 1980.00 @ 244.10
CANCEL BUY 1140.00 @ 244.13
CANCEL BUY -1940.00 @ 244.05
CANCEL BUY 2020.00 @ 244.02
CANCEL BUY 2020.00 @ 244.05
CANCEL BUY 1460.00 @ 244.17
CANCEL BUY 1140.00 @ 244.07
PASSIVE BUY 2060.00 @ 244.11
PASSIVE BUY 2380.00 @ 244.01
AGGRESSIVE BUY 2060.00 @ 244.20
AGGRESSIVE BUY 1860.00 @ 244.21
PASSIVE BUY 1460.00 @ 244.07
PASSIVE SELL 460.00 @ 244.20
PASSIVE SELL 1820.00 @ 244.17
AGGRESSIVE BUY 900.00 @ 244.17
PASSIVE BUY 980.00 @ 244.16
AGGRESSIVE BUY 2020.00 @ 244.21
PASSIVE BUY 2300.00 @ 244.07
PASSIVE BUY 1700.00 @ 244.20
PASSIVE SELL 2260.00 @ 244.28
PASSIVE SELL 740.00 @ 244.32
AGGRESSIVE BUY 2620.00 @ 244.24
AGGRESSIVE BUY 2820.00 @ 244.28
PASSIVE BUY 1380.00 @ 244.27
CANCEL BUY 2060.00 @ 244.11
CANCEL BUY 2380.00 @ 244.01
CANCEL BUY -1460.00 @ 244.07
CANCEL BUY 980.00 @ 244.16
CANCEL BUY 2300.00 @ 244.07
CANCEL BUY 1700.00 @ 244.20
CANCEL BUY 760.00 @ 244.24
CANCEL BUY 1380.00 @ 244.27
AGGRESSIVE BUY 1780.00 @ 244.32
PASSIVE BUY 1500.00 @ 244.13
PASSIVE SELL 980.00 @ 244.19
PASSIVE BUY 980.00 @ 244.02
AGGRESSIVE BUY 1740.00 @ 244.27
PASSIVE SELL 2140.00 @ 244.39
AGGRESSIVE BUY 1060.00 @ 244.39
PASSIVE BUY 1340.00 @ 244.18
PASSIVE SELL 460.00 @ 244.35
PASSIVE SELL 1740.00 @ 244.29
AGGRESSIVE BUY 2580.00 @ 244.39
PASSIVE BUY 1260.00 @ 244.22
AGGRESSIVE SELL 2100.00 @ 244.25
AGGRESSIVE BUY 1740.00 @ 244.31
AGGRESSIVE SELL 2060.00 @ 244.31
PASSIVE SELL 420.00 @ 244.25
PASSIVE BUY 1540.00 @ 244.12
AGGRESSIVE BUY 1660.00 @ 244.31
PASSIVE BUY 1540.00 @ 244.23
AGGRESSIVE BUY 2140.00 @ 244.35
CANCEL BUY 1500.00 @ 244.13
CANCEL BUY 980.00 @ 244.02
CANCEL BUY 1340.00 @ 244.18
CANCEL BUY 1260.00 @ 244.22
CANCEL BUY 1540.00 @ 244.12
CANCEL BUY 1540.00 @ 244.23
CANCEL BUY 1720.00 @ 244.35
PASSIVE SELL 1780.00 @ 244.49
PASSIVE SELL 1340.00 @ 244.32
PASSIVE BUY 2300.00 @ 244.21
PASSIVE SELL 1580.00 @ 244.31
AGGRESSIVE SELL 1020.00 @ 244.21
PASSIVE BUY 1620.00 @ 244.20
PASSIVE SELL 700.00 @ 244.22
PASSIVE SELL 460.00 @ 244.27
AGGRESSIVE SELL 2140.00 @ 244.20
AGGRESSIVE BUY 1820.00 @ 244.27
PASSIVE SELL 2100.00 @ 244.32
AGGRESSIVE SELL 1700.00 @ 244.25
PASSIVE SELL 2180.00 @ 244.21
AGGRESSIVE SELL 1100.00 @ 244.06
CANCEL SELL 1780.00 @ 244.49
AGGRESSIVE BUY 1020.00 @ 244.21
PASSIVE SELL 1260.00 @ 244.18
PASSIVE SELL 1100.00 @ 244.20
CANCEL SELL 740.00 @ 244.39
PASSIVE SELL 1260.00 @ 244.22
CANCEL SELL -1340.00 @ 244.32
CANCEL SELL 2100.00 @ 244.32
PASSIVE SELL 2300.00 @ 244.05
CANCEL SELL 1580.00 @ 244.31
PASSIVE BUY 1820.00 @ 244.03
AGGRESSIVE SELL 1140.00 @ 244.03
PASSIVE SELL 1100.00 @ 244.06
CANCEL SELL 1040.00 @ 244.25
PASSIVE SELL 1740.00 @ 244.17
CANCEL SELL 1260.00 @ 244.22
AGGRESSIVE SELL 700.00 @ 243.88
CANCEL SELL 1500.00 @ 244.21
AGGRESSIVE BUY 2500.00 @ 243.89
PASSIVE BUY 1740.00 @ 243.89
PASSIVE BUY 1260.00 @ 243.75
PASSIVE SELL 1740.00 @ 243.98
PASSIVE BUY 2900.00 @ 243.94
PASSIVE SELL 1580.00 @ 243.99
CANCEL SELL 1100.00 @ 244.20
PASSIVE BUY 1860.00 @ 243.94
AGGRESSIVE BUY 2420.00 @ 243.99
PASSIVE BUY 860.00 @ 243.92
AGGRESSIVE BUY 1380.00 @ 244.04
AGGRESSIVE SELL 1220.00 @ 243.98
PASSIVE BUY 780.00 @ 243.85
PASSIVE BUY 2300.00 @ 243.82
PASSIVE BUY 1020.00 @ 243.85
PASSIVE BUY 2500.00 @ 243.84
CANCEL BUY -2480.00 @ 243.89
CANCEL BUY 1740.00 @ 243.89
CANCEL BUY 1260.00 @ 243.75
CANCEL BUY -2900.00 @ 243.94
CANCEL BUY 1860.00 @ 243.94
CANCEL BUY 860.00 @ 243.92
CANCEL BUY -780.00 @ 243.85
CANCEL BUY 2300.00 @ 243.82
CANCEL BUY 1020.00 @ 243.85
CANCEL BUY 2500.00 @ 243.84
PASSIVE BUY 1860.00 @ 243.81
PASSIVE SELL 2140.00 @ 243.88
AGGRESSIVE BUY 1420.00 @ 243.88
PASSIVE BUY 2260.00 @ 243.86
PASSIVE SELL 2020.00 @ 243.87
CANCEL SELL 1260.00 @ 244.18
PASSIVE BUY 1340.00 @ 243.76
PASSIVE BUY 2460.00 @ 243.79
PASSIVE SELL 1980.00 @ 243.90
CANCEL SELL 1740.00 @ 244.17
AGGRESSIVE SELL 900.00 @ 243.86
PASSIVE BUY 1220.00 @ 243.77
AGGRESSIVE SELL 980.00 @ 243.86
PASSIVE BUY 2220.00 @ 243.76
PASSIVE BUY 2180.00 @ 243.77
AGGRESSIVE BUY 2940.00 @ 243.87
AGGRESSIVE BUY 2180.00 @ 243.90
PASSIVE BUY 1380.00 @ 243.77
AGGRESSIVE SELL 2260.00 @ 243.81
PASSIVE SELL 1180.00 @ 243.86
AGGRESSIVE SELL 1700.00 @ 243.79
PASSIVE SELL 780.00 @ 243.97
PASSIVE SELL 2220.00 @ 243.94
CANCEL SELL 1100.00 @ 244.06
PASSIVE SELL 1460.00 @ 243.89
CANCEL SELL 2300.00 @ 244.05
AGGRESSIVE SELL 1700.00 @ 243.77
PASSIVE SELL 460.00 @ 243.98
AGGRESSIVE BUY 1060.00 @ 243.86
PASSIVE BUY 2460.00 @ 243.75
PASSIVE SELL 1460.00 @ 243.87
CANCEL SELL -740.00 @ 243.98
CANCEL SELL 460.00 @ 243.98
PASSIVE SELL 860.00 @ 243.97
